<?xml version="1.0" encoding="UTF-8"?>
<testng-results skipped="0" failed="3" ignored="0" total="3" passed="0">
  <reporter-output>
  </reporter-output>
  <suite name="apitest" duration-ms="1625" started-at="2019-02-27T09:38:11Z" finished-at="2019-02-27T09:38:12Z">
    <groups>
    </groups>
    <test name="Default test" duration-ms="1625" started-at="2019-02-27T09:38:11Z" finished-at="2019-02-27T09:38:12Z">
      <class name="com.bitnei.apitest.testcases.datasend.TaskAdd">
        <test-method status="PASS" signature="setUp(java.lang.String)[pri:0, instance:com.bitnei.apitest.testcases.datasend.TaskAdd@61f8bee4]" name="setUp" is-config="true" duration-ms="1064" started-at="2019-02-27T09:38:11Z" finished-at="2019-02-27T09:38:12Z">
          <params>
            <param index="0">
              <value>
                <![CDATA[http://bdp-app.bitnei.cn:7788]]>
              </value>
            </param>
          </params>
          <reporter-output>
          </reporter-output>
        </test-method> <!-- setUp -->
        <test-method status="FAIL" signature="TaskAddData(java.lang.String)[pri:0, instance:com.bitnei.apitest.testcases.datasend.TaskAdd@61f8bee4]" name="TaskAddData" duration-ms="326" started-at="2019-02-27T09:38:12Z" description="数据转发平台新增任务" data-provider="dataprovider1" finished-at="2019-02-27T09:38:12Z">
          <params>
            <param index="0">
              <value>
                <![CDATA[{"status":200,"errorMsg":null,"data":null,"error":false}]]>
              </value>
            </param>
          </params>
          <exception class="java.lang.AssertionError">
            <message>
              <![CDATA[expected [{}] but found [{"status":{"currentValue is ":500,"expectedValue is":200},"error":{"currentValue is ":true,"expectedValue is":false}}]]]>
            </message>
            <full-stacktrace>
              <![CDATA[java.lang.AssertionError: expected [{}] but found [{"status":{"currentValue is ":500,"expectedValue is":200},"error":{"currentValue is ":true,"expectedValue is":false}}]
at org.testng.Assert.fail(Assert.java:96)
at org.testng.Assert.failNotEquals(Assert.java:776)
at org.testng.Assert.assertEqualsImpl(Assert.java:137)
at org.testng.Assert.assertEquals(Assert.java:118)
at org.testng.Assert.assertEquals(Assert.java:453)
at org.testng.Assert.assertEquals(Assert.java:463)
at com.bitnei.apitest.testcases.datasend.TaskAdd.TaskAddData(TaskAdd.java:85)
at sun.reflect.NativeMethodAccessorImpl.invoke0(Native Method)
at sun.reflect.NativeMethodAccessorImpl.invoke(NativeMethodAccessorImpl.java:62)
at sun.reflect.DelegatingMethodAccessorImpl.invoke(DelegatingMethodAccessorImpl.java:43)
at java.lang.reflect.Method.invoke(Method.java:498)
at org.testng.internal.MethodInvocationHelper.invokeMethod(MethodInvocationHelper.java:124)
at org.testng.internal.Invoker.invokeMethod(Invoker.java:580)
at org.testng.internal.Invoker.invokeTestMethod(Invoker.java:716)
at org.testng.internal.Invoker.invokeTestMethods(Invoker.java:988)
at org.testng.internal.TestMethodWorker.invokeTestMethods(TestMethodWorker.java:125)
at org.testng.internal.TestMethodWorker.run(TestMethodWorker.java:109)
at org.testng.TestRunner.privateRun(TestRunner.java:648)
at org.testng.TestRunner.run(TestRunner.java:505)
at org.testng.SuiteRunner.runTest(SuiteRunner.java:455)
at org.testng.SuiteRunner.runSequentially(SuiteRunner.java:450)
at org.testng.SuiteRunner.privateRun(SuiteRunner.java:415)
at org.testng.SuiteRunner.run(SuiteRunner.java:364)
at org.testng.SuiteRunnerWorker.runSuite(SuiteRunnerWorker.java:52)
at org.testng.SuiteRunnerWorker.run(SuiteRunnerWorker.java:84)
at org.testng.TestNG.runSuitesSequentially(TestNG.java:1208)
at org.testng.TestNG.runSuitesLocally(TestNG.java:1137)
at org.testng.TestNG.runSuites(TestNG.java:1049)
at org.testng.TestNG.run(TestNG.java:1017)
at org.testng.remote.AbstractRemoteTestNG.run(AbstractRemoteTestNG.java:114)
at org.testng.remote.RemoteTestNG.initAndRun(RemoteTestNG.java:251)
at org.testng.remote.RemoteTestNG.main(RemoteTestNG.java:77)
]]>
            </full-stacktrace>
          </exception> <!-- java.lang.AssertionError -->
          <reporter-output>
          </reporter-output>
        </test-method> <!-- TaskAddData -->
        <test-method status="FAIL" signature="TaskAddDataRep(java.lang.String)[pri:1, instance:com.bitnei.apitest.testcases.datasend.TaskAdd@61f8bee4]" name="TaskAddDataRep" duration-ms="95" started-at="2019-02-27T09:38:12Z" description="数据转发平台新增任务时目标平台重复" data-provider="dataprovider3" finished-at="2019-02-27T09:38:12Z">
          <params>
            <param index="0">
              <value>
                <![CDATA[{"status":500,"errorMsg":"该平台已分配，不能重复添加","data":null,"error":true}]]>
              </value>
            </param>
          </params>
          <exception class="java.lang.AssertionError">
            <message>
              <![CDATA[expected [{}] but found [{"errorMsg":{"currentValue is ":"服务器内部异常","expectedValue":"该平台已分配，不能重复添加"}}]]]>
            </message>
            <full-stacktrace>
              <![CDATA[java.lang.AssertionError: expected [{}] but found [{"errorMsg":{"currentValue is ":"服务器内部异常","expectedValue":"该平台已分配，不能重复添加"}}]
at org.testng.Assert.fail(Assert.java:96)
at org.testng.Assert.failNotEquals(Assert.java:776)
at org.testng.Assert.assertEqualsImpl(Assert.java:137)
at org.testng.Assert.assertEquals(Assert.java:118)
at org.testng.Assert.assertEquals(Assert.java:453)
at org.testng.Assert.assertEquals(Assert.java:463)
at com.bitnei.apitest.testcases.datasend.TaskAdd.TaskAddDataRep(TaskAdd.java:117)
at sun.reflect.NativeMethodAccessorImpl.invoke0(Native Method)
at sun.reflect.NativeMethodAccessorImpl.invoke(NativeMethodAccessorImpl.java:62)
at sun.reflect.DelegatingMethodAccessorImpl.invoke(DelegatingMethodAccessorImpl.java:43)
at java.lang.reflect.Method.invoke(Method.java:498)
at org.testng.internal.MethodInvocationHelper.invokeMethod(MethodInvocationHelper.java:124)
at org.testng.internal.Invoker.invokeMethod(Invoker.java:580)
at org.testng.internal.Invoker.invokeTestMethod(Invoker.java:716)
at org.testng.internal.Invoker.invokeTestMethods(Invoker.java:988)
at org.testng.internal.TestMethodWorker.invokeTestMethods(TestMethodWorker.java:125)
at org.testng.internal.TestMethodWorker.run(TestMethodWorker.java:109)
at org.testng.TestRunner.privateRun(TestRunner.java:648)
at org.testng.TestRunner.run(TestRunner.java:505)
at org.testng.SuiteRunner.runTest(SuiteRunner.java:455)
at org.testng.SuiteRunner.runSequentially(SuiteRunner.java:450)
at org.testng.SuiteRunner.privateRun(SuiteRunner.java:415)
at org.testng.SuiteRunner.run(SuiteRunner.java:364)
at org.testng.SuiteRunnerWorker.runSuite(SuiteRunnerWorker.java:52)
at org.testng.SuiteRunnerWorker.run(SuiteRunnerWorker.java:84)
at org.testng.TestNG.runSuitesSequentially(TestNG.java:1208)
at org.testng.TestNG.runSuitesLocally(TestNG.java:1137)
at org.testng.TestNG.runSuites(TestNG.java:1049)
at org.testng.TestNG.run(TestNG.java:1017)
at org.testng.remote.AbstractRemoteTestNG.run(AbstractRemoteTestNG.java:114)
at org.testng.remote.RemoteTestNG.initAndRun(RemoteTestNG.java:251)
at org.testng.remote.RemoteTestNG.main(RemoteTestNG.java:77)
]]>
            </full-stacktrace>
          </exception> <!-- java.lang.AssertionError -->
          <reporter-output>
          </reporter-output>
        </test-method> <!-- TaskAddDataRep -->
        <test-method status="FAIL" signature="TaskAddDataRepTask(java.lang.String)[pri:2, instance:com.bitnei.apitest.testcases.datasend.TaskAdd@61f8bee4]" name="TaskAddDataRepTask" duration-ms="95" started-at="2019-02-27T09:38:12Z" description="数据转发平台新增任务时目标任务名称重复" data-provider="dataprovider4" finished-at="2019-02-27T09:38:12Z">
          <params>
            <param index="0">
              <value>
                <![CDATA[{"status":500,"errorMsg":"任务名称已存在","data":null,"error":true}]]>
              </value>
            </param>
          </params>
          <exception class="java.lang.AssertionError">
            <message>
              <![CDATA[expected [{}] but found [{"errorMsg":{"currentValue is ":"服务器内部异常","expectedValue":"任务名称已存在"}}]]]>
            </message>
            <full-stacktrace>
              <![CDATA[java.lang.AssertionError: expected [{}] but found [{"errorMsg":{"currentValue is ":"服务器内部异常","expectedValue":"任务名称已存在"}}]
at org.testng.Assert.fail(Assert.java:96)
at org.testng.Assert.failNotEquals(Assert.java:776)
at org.testng.Assert.assertEqualsImpl(Assert.java:137)
at org.testng.Assert.assertEquals(Assert.java:118)
at org.testng.Assert.assertEquals(Assert.java:453)
at org.testng.Assert.assertEquals(Assert.java:463)
at com.bitnei.apitest.testcases.datasend.TaskAdd.TaskAddDataRepTask(TaskAdd.java:149)
at sun.reflect.NativeMethodAccessorImpl.invoke0(Native Method)
at sun.reflect.NativeMethodAccessorImpl.invoke(NativeMethodAccessorImpl.java:62)
at sun.reflect.DelegatingMethodAccessorImpl.invoke(DelegatingMethodAccessorImpl.java:43)
at java.lang.reflect.Method.invoke(Method.java:498)
at org.testng.internal.MethodInvocationHelper.invokeMethod(MethodInvocationHelper.java:124)
at org.testng.internal.Invoker.invokeMethod(Invoker.java:580)
at org.testng.internal.Invoker.invokeTestMethod(Invoker.java:716)
at org.testng.internal.Invoker.invokeTestMethods(Invoker.java:988)
at org.testng.internal.TestMethodWorker.invokeTestMethods(TestMethodWorker.java:125)
at org.testng.internal.TestMethodWorker.run(TestMethodWorker.java:109)
at org.testng.TestRunner.privateRun(TestRunner.java:648)
at org.testng.TestRunner.run(TestRunner.java:505)
at org.testng.SuiteRunner.runTest(SuiteRunner.java:455)
at org.testng.SuiteRunner.runSequentially(SuiteRunner.java:450)
at org.testng.SuiteRunner.privateRun(SuiteRunner.java:415)
at org.testng.SuiteRunner.run(SuiteRunner.java:364)
at org.testng.SuiteRunnerWorker.runSuite(SuiteRunnerWorker.java:52)
at org.testng.SuiteRunnerWorker.run(SuiteRunnerWorker.java:84)
at org.testng.TestNG.runSuitesSequentially(TestNG.java:1208)
at org.testng.TestNG.runSuitesLocally(TestNG.java:1137)
at org.testng.TestNG.runSuites(TestNG.java:1049)
at org.testng.TestNG.run(TestNG.java:1017)
at org.testng.remote.AbstractRemoteTestNG.run(AbstractRemoteTestNG.java:114)
at org.testng.remote.RemoteTestNG.initAndRun(RemoteTestNG.java:251)
at org.testng.remote.RemoteTestNG.main(RemoteTestNG.java:77)
]]>
            </full-stacktrace>
          </exception> <!-- java.lang.AssertionError -->
          <reporter-output>
          </reporter-output>
        </test-method> <!-- TaskAddDataRepTask -->
      </class> <!-- com.bitnei.apitest.testcases.datasend.TaskAdd -->
    </test> <!-- Default test -->
  </suite> <!-- apitest -->
</testng-results>
