<?xml version="1.0" encoding="UTF-8"?>
<!-- Generated by org.testng.reporters.JUnitReportReporter -->
<testsuite skipped="0" hostname="DESKTOP-Q37MKND" name="com.bitnei.apitest.testcases.datasend.TaskAdd" tests="3" failures="3" timestamp="12 三月 2019 10:44:11 GMT" time="0.908" errors="0">
  <testcase name="TaskAddData" time="0.322" classname="com.bitnei.apitest.testcases.datasend.TaskAdd">
    <failure type="java.lang.AssertionError" message="expected [{}] but found [{&quot;status&quot;:{&quot;currentValue is &quot;:500,&quot;expectedValue is&quot;:200},&quot;error&quot;:{&quot;currentValue is &quot;:true,&quot;expectedValue is&quot;:false}}]">
      <![CDATA[java.lang.AssertionError: expected [{}] but found [{"status":{"currentValue is ":500,"expectedValue is":200},"error":{"currentValue is ":true,"expectedValue is":false}}]
at org.testng.Assert.fail(Assert.java:96)
at org.testng.Assert.failNotEquals(Assert.java:776)
at org.testng.Assert.assertEqualsImpl(Assert.java:137)
at org.testng.Assert.assertEquals(Assert.java:118)
at org.testng.Assert.assertEquals(Assert.java:453)
at org.testng.Assert.assertEquals(Assert.java:463)
at com.bitnei.apitest.testcases.datasend.TaskAdd.TaskAddData(TaskAdd.java:85)
at sun.reflect.NativeMethodAccessorImpl.invoke0(Native Method)
at sun.reflect.NativeMethodAccessorImpl.invoke(NativeMethodAccessorImpl.java:62)
at sun.reflect.DelegatingMethodAccessorImpl.invoke(DelegatingMethodAccessorImpl.java:43)
at java.lang.reflect.Method.invoke(Method.java:498)
at org.testng.internal.MethodInvocationHelper.invokeMethod(MethodInvocationHelper.java:124)
at org.testng.internal.Invoker.invokeMethod(Invoker.java:580)
at org.testng.internal.Invoker.invokeTestMethod(Invoker.java:716)
at org.testng.internal.Invoker.invokeTestMethods(Invoker.java:988)
at org.testng.internal.TestMethodWorker.invokeTestMethods(TestMethodWorker.java:125)
at org.testng.internal.TestMethodWorker.run(TestMethodWorker.java:109)
at java.util.concurrent.ThreadPoolExecutor.runWorker(ThreadPoolExecutor.java:1149)
at java.util.concurrent.ThreadPoolExecutor$Worker.run(ThreadPoolExecutor.java:624)
at java.lang.Thread.run(Thread.java:748)
]]>
    </failure>
  </testcase> <!-- TaskAddData -->
  <testcase name="TaskAddDataRep" time="0.512" classname="com.bitnei.apitest.testcases.datasend.TaskAdd">
    <failure type="java.lang.AssertionError" message="expected [{}] but found [{&quot;errorMsg&quot;:{&quot;currentValue is &quot;:&quot;服务器内部异常&quot;,&quot;expectedValue&quot;:&quot;该平台已分配，不能重复添加&quot;}}]">
      <![CDATA[java.lang.AssertionError: expected [{}] but found [{"errorMsg":{"currentValue is ":"服务器内部异常","expectedValue":"该平台已分配，不能重复添加"}}]
at org.testng.Assert.fail(Assert.java:96)
at org.testng.Assert.failNotEquals(Assert.java:776)
at org.testng.Assert.assertEqualsImpl(Assert.java:137)
at org.testng.Assert.assertEquals(Assert.java:118)
at org.testng.Assert.assertEquals(Assert.java:453)
at org.testng.Assert.assertEquals(Assert.java:463)
at com.bitnei.apitest.testcases.datasend.TaskAdd.TaskAddDataRep(TaskAdd.java:117)
at sun.reflect.NativeMethodAccessorImpl.invoke0(Native Method)
at sun.reflect.NativeMethodAccessorImpl.invoke(NativeMethodAccessorImpl.java:62)
at sun.reflect.DelegatingMethodAccessorImpl.invoke(DelegatingMethodAccessorImpl.java:43)
at java.lang.reflect.Method.invoke(Method.java:498)
at org.testng.internal.MethodInvocationHelper.invokeMethod(MethodInvocationHelper.java:124)
at org.testng.internal.Invoker.invokeMethod(Invoker.java:580)
at org.testng.internal.Invoker.invokeTestMethod(Invoker.java:716)
at org.testng.internal.Invoker.invokeTestMethods(Invoker.java:988)
at org.testng.internal.TestMethodWorker.invokeTestMethods(TestMethodWorker.java:125)
at org.testng.internal.TestMethodWorker.run(TestMethodWorker.java:109)
at java.util.concurrent.ThreadPoolExecutor.runWorker(ThreadPoolExecutor.java:1149)
at java.util.concurrent.ThreadPoolExecutor$Worker.run(ThreadPoolExecutor.java:624)
at java.lang.Thread.run(Thread.java:748)
]]>
    </failure>
  </testcase> <!-- TaskAddDataRep -->
  <testcase name="TaskAddDataRepTask" time="0.074" classname="com.bitnei.apitest.testcases.datasend.TaskAdd">
    <failure type="java.lang.AssertionError" message="expected [{}] but found [{&quot;errorMsg&quot;:{&quot;currentValue is &quot;:&quot;服务器内部异常&quot;,&quot;expectedValue&quot;:&quot;任务名称已存在&quot;}}]">
      <![CDATA[java.lang.AssertionError: expected [{}] but found [{"errorMsg":{"currentValue is ":"服务器内部异常","expectedValue":"任务名称已存在"}}]
at org.testng.Assert.fail(Assert.java:96)
at org.testng.Assert.failNotEquals(Assert.java:776)
at org.testng.Assert.assertEqualsImpl(Assert.java:137)
at org.testng.Assert.assertEquals(Assert.java:118)
at org.testng.Assert.assertEquals(Assert.java:453)
at org.testng.Assert.assertEquals(Assert.java:463)
at com.bitnei.apitest.testcases.datasend.TaskAdd.TaskAddDataRepTask(TaskAdd.java:149)
at sun.reflect.NativeMethodAccessorImpl.invoke0(Native Method)
at sun.reflect.NativeMethodAccessorImpl.invoke(NativeMethodAccessorImpl.java:62)
at sun.reflect.DelegatingMethodAccessorImpl.invoke(DelegatingMethodAccessorImpl.java:43)
at java.lang.reflect.Method.invoke(Method.java:498)
at org.testng.internal.MethodInvocationHelper.invokeMethod(MethodInvocationHelper.java:124)
at org.testng.internal.Invoker.invokeMethod(Invoker.java:580)
at org.testng.internal.Invoker.invokeTestMethod(Invoker.java:716)
at org.testng.internal.Invoker.invokeTestMethods(Invoker.java:988)
at org.testng.internal.TestMethodWorker.invokeTestMethods(TestMethodWorker.java:125)
at org.testng.internal.TestMethodWorker.run(TestMethodWorker.java:109)
at java.util.concurrent.ThreadPoolExecutor.runWorker(ThreadPoolExecutor.java:1149)
at java.util.concurrent.ThreadPoolExecutor$Worker.run(ThreadPoolExecutor.java:624)
at java.lang.Thread.run(Thread.java:748)
]]>
    </failure>
  </testcase> <!-- TaskAddDataRepTask -->
</testsuite> <!-- com.bitnei.apitest.testcases.datasend.TaskAdd -->
